<?xml version="1.0" encoding="utf-8"?>
<!-- This URDF was automatically created by SolidWorks to URDF Exporter! Originally created by Stephen Brawner (brawner@gmail.com) 
     Commit Version: 1.6.0-4-g7f85cfe  Build Version: 1.6.7995.38578
     For more information, please see http://wiki.ros.org/sw_urdf_exporter -->
<robot
  name="HJBUT">
  <link
    name="base_link">
    <visual>
      <origin
        xyz="0 0 0"
        rpy="0 0 0" />
      <geometry>
        <mesh
          filename="base_link.STL" />
      </geometry>
      <material
        name="">
        <color
          rgba="1 1 1 1" />
      </material>
    </visual>
    <collision>
      <origin
        xyz="0 0 0"
        rpy="0 0 0" />
      <geometry>
        <mesh
          filename="base_link.STL" />
      </geometry>
    </collision>
  </link>
  <link
    name="link1">
    <inertial>
      <origin
        xyz="0.160918 -0.000015 -0.017888"
        rpy="0 0 0" />
      <mass
        value="3.527" />
      <inertia
        ixx="0.315591824016712"
        ixy="-0.0357991195031827"
        ixz="-0.224419290508745"
        iyy="0.608728022142769"
        iyz="-0.0424220871654391"
        izz="0.339344724690997" />
    </inertial>
    <visual>
      <origin
        xyz="0 0 0"
        rpy="0 0 0" />
      <geometry>
        <mesh
          filename="link1.STL" />
      </geometry>
      <material
        name="">
        <color
          rgba="1 1 1 1" />
      </material>
    </visual>
    <collision>
      <origin
        xyz="0 0 0"
        rpy="0 0 0" />
      <geometry>
        <mesh
          filename="link1.STL" />
      </geometry>
    </collision>
  </link>
  <joint
    name="joint1"
    type="continuous">
    <origin
      xyz="0 0 0"
      rpy="1.5707963267949 -1.5707963267949 3.1415926" />
    <parent
      link="base_link" />
    <child
      link="link1" />
    <axis
      xyz="0 0 1" />
      <hardware id="0" type="driver">
            <limit lower="-6.28" upper="6.28"  vel="3.0" acc="10.0" jerk="150.0" effort="30.0"/>
            <transform ratio="1.0" offset_pos_cnt="0" cnt_per_unit="20860.7570568" torque_per_unit="1.0"
                       user_unit_name="rad"/>
             <inputs name="Inputs">
                <status_word>Statusword</status_word>
                <position_actual_value>Position actual value</position_actual_value>
                <velocity_actual_value>Velocity actual value</velocity_actual_value>
                <torque_actual_value>Torque actual value</torque_actual_value>
                <load_torque_value>Analog Input 1</load_torque_value>
                <secondary_position_value>Auxiliary position actual value</secondary_position_value>
                <!-- <secondary_velocity_value>Secondary velocity value</secondary_velocity_value> -->
            </inputs>
            <outputs name="Outputs">
                <control_word>Controlword</control_word>
                <mode_of_operation>Modes of operation</mode_of_operation>
                <target_position>Target position</target_position>
                <target_velocity>Target velocity</target_velocity>
                <target_torque>Target torque</target_torque>
            </outputs>        
        </hardware>
  </joint>
  <link
    name="link_2">
    <inertial>
      <origin
        xyz="0.086844 -0.000004 -0.004985"
        rpy="0 0 0" />
      <mass
        value="1.299" />
      <inertia
        ixx="0.315591824016712"
        ixy="-0.0357991195031827"
        ixz="-0.224419290508745"
        iyy="0.608728022142769"
        iyz="-0.0424220871654391"
        izz="0.339344724690997" />
    </inertial>
    <visual>
      <origin
        xyz="0 0 0"
        rpy="0 0 0" />
      <geometry>
        <mesh
          filename="link2.STL" />
      </geometry>
      <material
        name="">
        <color
          rgba="1 1 1 1" />
      </material>
    </visual>
    <collision>
      <origin
        xyz="0 0 0"
        rpy="0 0 0" />
      <geometry>
        <mesh
          filename="link2.STL" />
      </geometry>
    </collision>
  </link>
  <joint
    name="joint2"
    type="continuous">
    <origin
      xyz="0.279999999666084 0 0.0355"
      rpy="0 0 0" />
    <parent
      link="link1" />
    <child
      link="link_2" />
    <axis    xyz="0 0 1" />
    <hardware id="1" type="driver">
            <limit lower="-6.28" upper="6.28" vel="3.0" acc="10.0" jerk="150.0" effort="30.0" />
            <transform ratio="1.0" offset_pos_cnt="0" cnt_per_unit="20860.7570568" torque_per_unit="1.0" user_unit_name="rad"/>
            <inputs name="Inputs">
                <status_word>Statusword</status_word>
                <position_actual_value>Position actual value</position_actual_value>
                <velocity_actual_value>Velocity actual value</velocity_actual_value>
                <torque_actual_value>Torque actual value</torque_actual_value>
                <load_torque_value>Analog Input 1</load_torque_value>
                <secondary_position_value>Auxiliary position actual value</secondary_position_value>
                <!-- <secondary_velocity_value>Secondary velocity value</secondary_velocity_value> -->
            </inputs>
            <outputs name="Outputs">
                <control_word>Controlword</control_word>
                <mode_of_operation>Modes of operation</mode_of_operation>
                <target_position>Target position</target_position>
                <target_velocity>Target velocity</target_velocity>
                <target_torque>Target torque</target_torque>
            </outputs>  
        </hardware>


   
  </joint>
  <link
    name="link_3">
  </link>
  <joint
    name="joint3"
    type="fixed">
    <origin
      xyz="0.28 0 0"
      rpy="0 0 0" />
    <parent
      link="link_2" />
    <child
      link="link_3" />
    

   
  </joint>
</robot>