<?xml version="1.0" encoding="utf-8"?>
<!-- This URDF was automatically created by SolidWorks to URDF Exporter! Originally created by Stephen Brawner (brawner@gmail.com) 
     Commit Version: 1.6.0-1-g15f4949  Build Version: 1.6.7594.29634
     For more information, please see http://wiki.ros.org/sw_urdf_exporter -->
<robot name="sia_robot">
    <link name="base_link">
        <visual>
            <origin xyz="0 0 0" rpy="0 0 0"/>
            <geometry>
                <mesh filename="package://taike_robot arm_urdf/meshes/base_link.STL"/>
            </geometry>
            <material name="">
                <color rgba="1 1 1 1"/>
            </material>
        </visual>
        <collision>
            <origin xyz="0 0 0" rpy="0 0 0"/>
            <geometry>
                <mesh filename="package://taike_robot arm_urdf/meshes/base_link.STL"/>
            </geometry>
        </collision>
    </link>
    <link name="link_1">
        <visual>
            <origin xyz="0 0 0" rpy="0 0 0"/>
            <geometry>
                <mesh filename="package://taike_robot arm_urdf/meshes/link_1.STL"/>
            </geometry>
            <material name="">
                <color rgba="1 1 1 1"/>
            </material>
        </visual>
        <collision>
            <origin xyz="0 0 0" rpy="0 0 0"/>
            <geometry>
                <mesh filename="package://taike_robot arm_urdf/meshes/link_1.STL"/>
            </geometry>
        </collision>
    </link>
    <joint name="joint_1" type="continuous">
        <origin xyz="0.0 0.0 0.3393" rpy="0 0 0"/>
        <parent link="base_link"/>
        <child link="link_1"/>
        <axis xyz="0 0 1"/>
        <hardware id="0">
            <limit lower="-2.932" upper="2.932" vel="1.0" acc="10.0" jerk="10.0" effort="30.0"/>
            <transform ratio="1.0" offset_pos_cnt="458752" cnt_per_unit="156455.678" torque_per_unit="1.0"
                       user_unit_name="rad"/>
        </hardware>
    </joint>
    <link name="link_2">
        <inertial>
            <origin xyz="0.12727 2.9785E-07 0.0044026" rpy="0 0 0"/>
            <mass value="2.3222"/>
            <inertia ixx="0.0033504" ixy="-1.9329E-07" ixz="0.00024826"
                     iyy="0.038629" iyz="-1.8337E-09"
                     izz="0.037222"/>
        </inertial>
        <visual>
            <origin xyz="0 0 0" rpy="0 0 0"/>
            <geometry>
                <mesh filename="package://taike_robot arm_urdf/meshes/link_2.STL"/>
            </geometry>
            <material name="">
                <color rgba="1 1 1 1"/>
            </material>
        </visual>
        <collision>
            <origin xyz="0 0 0" rpy="0 0 0"/>
            <geometry>
                <mesh filename="package://taike_robot arm_urdf/meshes/link_2.STL"/>
            </geometry>
        </collision>
    </link>
    <joint name="joint_2" type="continuous">
        <origin xyz="0 0 0" rpy="1.5708 0 0"/>
        <parent link="link_1"/>
        <child link="link_2"/>
        <axis xyz="0 0 1"/>
        <hardware id="1">
            <limit lower="-2.28" upper="2.28" vel="1.0" acc="10.0" jerk="10.0" effort="30.0" />
            <transform ratio="1.0" offset_pos_cnt="361813" cnt_per_unit="156455.678" torque_per_unit="1.0" user_unit_name="rad"/>
        </hardware>
    </joint>
    <link name="link_3">
        <inertial>
            <origin xyz="0.155146756102727 1.69273745565068E-05 0.101933463705677" rpy="0 0 0"/>
            <mass value="1.22157164179203"/>
            <inertia ixx="0.00109587279988836" ixy="3.09669167464475E-06" ixz="-0.00129294542904466"
                     iyy="0.0150983547059232" iyz="6.21914055513365E-07"
                     izz="0.014642955242962"/>
        </inertial>
        <visual>
            <origin xyz="0 0 0" rpy="0 0 0"/>
            <geometry>
                <mesh filename="package://taike_robot arm_urdf/meshes/link_3.STL"/>
            </geometry>
            <material name="">
                <color rgba="1 1 1 1"/>
            </material>
        </visual>
        <collision>
            <origin xyz="0 0 0" rpy="0 0 0"/>
            <geometry>
                <mesh filename="package://taike_robot arm_urdf/meshes/link_3.STL"/>
            </geometry>
        </collision>
    </link>
    <joint name="joint_3" type="continuous">
        <origin xyz="0 0.3977 0" rpy="-1.5708 0 0"/>
        <parent link="link_2"/>
        <child link="link_3"/>
        <axis xyz="0 0 1"/>
        <hardware id="2">
            <limit lower="-2.95" upper="2.95" vel="1.0" acc="10.0" jerk="10.0" effort="30.0" />
            <transform ratio="1.0" offset_pos_cnt="461483" cnt_per_unit="156455.678" torque_per_unit="1.0" user_unit_name="rad"/>
        </hardware>
    </joint>
    <link name="link_4">
        <inertial>
            <origin xyz="-2.4711E-07 -0.010264 -0.004748" rpy="0 0 0"/>
            <mass value="0.45068"/>
            <inertia ixx="0.00061623" ixy="3.4687E-09" ixz="1.1596E-09"
                     iyy="0.00030262" iyz="2.1617E-05"
                     izz="0.00057068"/>
        </inertial>
        <visual>
            <origin xyz="0 0 0" rpy="0 0 0"/>
            <geometry>
                <mesh filename="package://taike_robot arm_urdf/meshes/link_4.STL"/>
            </geometry>
            <material name="">
                <color rgba="1 1 1 1"/>
            </material>
        </visual>
        <collision>
            <origin xyz="0 0 0"
                    rpy="0 0 0"/>
            <geometry>
                <mesh filename="package://taike_robot arm_urdf/meshes/link_4.STL"/>
            </geometry>
        </collision>
    </link>
    <joint name="joint_4" type="continuous">
        <origin xyz="0 0 0" rpy="1.5708 0 0"/>
        <parent link="link_3"/>
        <child link="link_4"/>
        <axis xyz="0 0 1"/>
        <hardware id="3">
            <limit lower="-2.30" upper="2.30" vel="1.0" acc="10.0" jerk="10.0" effort="30.0" />
            <transform ratio="1.0" offset_pos_cnt="361811" cnt_per_unit="156455.678" torque_per_unit="1.0" user_unit_name="rad"/>
        </hardware>
    </joint>
    <link name="link_5">
        <inertial>
            <origin xyz="3.1874E-07 0.010265 -0.0047482" rpy="0 0 0"/>
            <mass value="0.45069"/>
            <inertia ixx="0.00061624" ixy="3.4201E-09" ixz="-1.323E-09"
                     iyy="0.00030262" iyz="-2.1613E-05"
                     izz="0.0005707"/>
        </inertial>
        <visual>
            <origin xyz="0 0 0" rpy="0 0 0"/>
            <geometry>
                <mesh filename="package://taike_robot arm_urdf/meshes/link_5.STL"/>
            </geometry>
            <material name="">
                <color rgba="1 1 1 1"/>
            </material>
        </visual>
        <collision>
            <origin xyz="0 0 0" rpy="0 0 0"/>
            <geometry>
                <mesh filename="package://taike_robot arm_urdf/meshes/link_5.STL"/>
            </geometry>
        </collision>
    </link>
    <joint name="joint_5" type="continuous">
        <origin xyz="0 0.3925 0" rpy="-1.5708 0 0"/>
        <parent link="link_4"/>
        <child link="link_5"/>
        <axis xyz="0 0 1"/>
        <hardware id="4">
            <limit lower="-2.78" upper="2.78" vel="1.0" acc="10.0" jerk="10.0" effort="30.0" />
            <transform ratio="1.0" offset_pos_cnt="483328" cnt_per_unit="156455.678" torque_per_unit="1.0" user_unit_name="rad"/>
        </hardware>
    </joint>
    <link name="link_6">
        <inertial>
            <origin xyz="-2.0889E-08 -0.00050715 -0.020114" rpy="0 0 0"/>
            <mass value="0.11516"/>
            <inertia ixx="4.3712E-05" ixy="-5.6644E-11" ixz="1.6692E-11"
                     iyy="4.2018E-05" iyz="6.31E-07"
                     izz="6.3255E-05"/>
        </inertial>
        <visual>
            <origin xyz="0 0 0" rpy="0 0 0"/>
            <geometry>
                <mesh filename="package://taike_robot arm_urdf/meshes/link_6.STL"/>
            </geometry>
            <material name="">
                <color rgba="1 1 1 1"/>
            </material>
        </visual>
        <collision>
            <origin xyz="0 0 0" rpy="0 0 0"/>
            <geometry>
                <mesh filename="package://taike_robot arm_urdf/meshes/link_6.STL"/>
            </geometry>
        </collision>
    </link>
    <joint name="joint_6" type="continuous">
        <origin xyz="0 0 0" rpy="1.5708 0 0"/>
        <parent link="link_5"/>
        <child link="link_6"/>
        <axis xyz="0 0 1"/>
        <hardware id="5">
            <limit lower="-2.172" upper="2.172" vel="1.0" acc="10.0" jerk="10.0" effort="30.0" />
            <transform ratio="1.0" offset_pos_cnt="283307" cnt_per_unit="130379.73" torque_per_unit="1.0" user_unit_name="rad"/>
        </hardware>
    </joint>
    <link name="link_7">
        <inertial>
            <origin xyz="-2.0889E-08 -0.00050715 -0.020114" rpy="0 0 0"/>
            <mass value="0.11516"/>
            <inertia ixx="4.3712E-05" ixy="-5.6644E-11" ixz="1.6692E-11"
                     iyy="4.2018E-05" iyz="6.31E-07"
                     izz="6.3255E-05"/>
        </inertial>
        <visual>
            <origin xyz="0 0 0" rpy="0 0 0"/>
            <geometry>
                <mesh filename="package://taike_robot arm_urdf/meshes/link_6.STL"/>
            </geometry>
            <material name="">
                <color rgba="1 1 1 1"/>
            </material>
        </visual>
        <collision>
            <origin xyz="0 0 0" rpy="0 0 0"/>
            <geometry>
                <mesh filename="package://taike_robot arm_urdf/meshes/link_6.STL"/>
            </geometry>
        </collision>
    </link>
    <joint name="joint_7" type="continuous">
        <origin xyz="0 0.2145 0" rpy="-1.5708 0 0"/>
        <parent link="link_6"/>
        <child link="link_7"/>
        <axis xyz="0 0 1"/>
        <hardware id="6">
            <limit lower="-2.92" upper="2.92" vel="1.0" acc="10.0" jerk="10.0" effort="30.0" />
            <transform ratio="1.0" offset_pos_cnt="384569" cnt_per_unit="130379.73" torque_per_unit="1.0" user_unit_name="rad"/>
        </hardware>
    </joint>
</robot>