<?xml version="1.0" encoding="utf-8"?>
<!-- This URDF was automatically created by SolidWorks to URDF Exporter! Originally created by Stephen Brawner (brawner@gmail.com) 
     Commit Version: 1.6.0-1-g15f4949  Build Version: 1.6.7594.29634
     For more information, please see http://wiki.ros.org/sw_urdf_exporter -->
<robot name="sia_robot">
    <link name="base_link">
        <visual>
            <origin xyz="0 0 0" rpy="0 0 0"/>
            <geometry>
                <mesh filename="package://taike_robot arm_urdf/meshes/base_link.STL"/>
            </geometry>
            <material name="">
                <color rgba="1 1 1 1"/>
            </material>
        </visual>
        <collision>
            <origin xyz="0 0 0" rpy="0 0 0"/>
            <geometry>
                <mesh filename="package://taike_robot arm_urdf/meshes/base_link.STL"/>
            </geometry>
        </collision>
    </link>
    <link name="link_1">
        <visual>
            <origin xyz="0 0 0" rpy="0 0 0"/>
            <geometry>
                <mesh filename="package://taike_robot arm_urdf/meshes/link_1.STL"/>
            </geometry>
            <material name="">
                <color rgba="1 1 1 1"/>
            </material>
        </visual>
        <collision>
            <origin xyz="0 0 0" rpy="0 0 0"/>
            <geometry>
                <mesh filename="package://taike_robot arm_urdf/meshes/link_1.STL"/>
            </geometry>
        </collision>
    </link>
    <joint name="joint_1" type="continuous">
        <origin xyz="0.0 0.0 0.1215" rpy="0 0 0"/>
        <parent link="base_link"/>
        <child link="link_1"/>
        <axis xyz="0 0 1"/>
       <hardware id="0">
            <limit lower="-6.28" upper="6.28" vel="1.0" acc="10.0" jerk="100.0" effort="30.0"/>
            <transform ratio="1.0" offset_pos_cnt="926217.61376" cnt_per_unit="156455.678" torque_per_unit="1.0" user_unit_name="rad"/>
        </hardware>
    </joint>


</robot>